Workbook
Name Labortage: Termine!$B$22:$B$41
Name PauseEnde: Termine!$D$45
Name PauseStart: Termine!$B$45

Sheet Arbeitsplan
A1: Arbeitsplan — Dynamik Keltischer Wackelsteine | F1: Stand: | G1: =TODAY() -> 46317
B2: Legende (Namen überschreibbar): | C2: Kristijan | D2: Janosch | E2: Beide | F2: offen | J2: ◆ | K2: Abgabe | M2: ● | N2: Praktikumstag | Q2: Praktikumspause | T2: aktuelle KW | W2: Gruppe (Summe)
A3: Projektpraktikum WS 26/27 · Universität Ulm · Kristijan & Janosch
A4: Nr | B4: Aufgabe | C4: Wer | D4: Start | E4: Ende | F4: Tage | G4: Status | H4: Typ | J4: KW 42 | K4: KW 43 | L4: KW 44 | M4: KW 45 | N4: KW 46 | O4: KW 47 | P4: KW 48 | Q4: KW 49 | R4: KW 50 | S4: KW 51 | T4: KW 52 | U4: KW 53 | V4: KW 1 | W4: KW 2 | X4: KW 3 | Y4: KW 4 | Z4: KW 5 | AA4: KW 6 | AB4: KW 7 | AC4: KW 8 | AD4: KW 9 | AE4: KW 10 | AF4: KW 11
J5: 46307 | K5: 46314 | L5: 46321 | M5: 46328 | N5: 46335 | O5: 46342 | P5: 46349 | Q5: 46356 | R5: 46363 | S5: 46370 | T5: 46377 | U5: 46384 | V5: 46391 | W5: 46398 | X5: 46405 | Y5: 46412 | Z5: 46419 | AA5: 46426 | AB5: 46433 | AC5: 46440 | AD5: 46447 | AE5: 46454 | AF5: 46461
J6: =J5+6 -> 46313 | K6: =K5+6 -> 46320 | L6: =L5+6 -> 46327 | M6: =M5+6 -> 46334 | N6: =N5+6 -> 46341 | O6: =O5+6 -> 46348 | P6: =P5+6 -> 46355 | Q6: =Q5+6 -> 46362 | ... AF6: =AF5+6 -> 46467
B7: ◆ Abgaben (Moodle / Portal) | J7: =REPT("◆",COUNTIFS($D$9:$D$85,">="&J$5,$D$9:$D$85,"<="&J$6,$H$9:$H$85,"M")) -> ◆ | K7: =REPT("◆",COUNTIFS($D$9:$D$85,">="&K$5,$D$9:$D$85,"<="&K$6,$H$9:$H$85,"M")) -> ◆ | L7: =REPT("◆",COUNTIFS($D$9:$D$85,">="&L$5,$D$9:$D$85,"<="&L$6,$H$9:$H$85,"M")) -> ◆ | M7: =REPT("◆",COUNTIFS($D$9:$D$85,">="&M$5,$D$9:$D$85,"<="&M$6,$H$9:$H$85,"M")) | N7: =REPT("◆",COUNTIFS($D$9:$D$85,">="&N$5,$D$9:$D$85,"<="&N$6,$H$9:$H$85,"M")) -> ◆ | O7: =REPT("◆",COUNTIFS($D$9:$D$85,">="&O$5,$D$9:$D$85,"<="&O$6,$H$9:$H$85,"M")) | P7: =REPT("◆",COUNTIFS($D$9:$D$85,">="&P$5,$D$9:$D$85,"<="&P$6,$H$9:$H$85,"M")) | Q7: =REPT("◆",COUNTIFS($D$9:$D$85,">="&Q$5,$D$9:$D$85,"<="&Q$6,$H$9:$H$85,"M")) | ... AF7: =REPT("◆",COUNTIFS($D$9:$D$85,">="&AF$5,$D$9:$D$85,"<="&AF$6,$H$9:$H$85,"M")) -> ◆
B8: ● Praktikumstage | J8: =IF(COUNTIFS(Labortage,">="&J$5,Labortage,"<="&J$6)>0,"●","") -> ● | K8: =IF(COUNTIFS(Labortage,">="&K$5,Labortage,"<="&K$6)>0,"●","") -> ● | L8: =IF(COUNTIFS(Labortage,">="&L$5,Labortage,"<="&L$6)>0,"●","") -> ● | M8: =IF(COUNTIFS(Labortage,">="&M$5,Labortage,"<="&M$6)>0,"●","") -> ● | N8: =IF(COUNTIFS(Labortage,">="&N$5,Labortage,"<="&N$6)>0,"●","") -> ● | O8: =IF(COUNTIFS(Labortage,">="&O$5,Labortage,"<="&O$6)>0,"●","") -> ● | P8: =IF(COUNTIFS(Labortage,">="&P$5,Labortage,"<="&P$6)>0,"●","") -> ● | Q8: =IF(COUNTIFS(Labortage,">="&Q$5,Labortage,"<="&Q$6)>0,"●","") -> ● | ... AF8: =IF(COUNTIFS(Labortage,">="&AF$5,Labortage,"<="&AF$6)>0,"●","")
A9: 1 | B9: Theorie & Literatur | D9: =MIN(D10:D16) -> 46310 | E9: =MAX(E10:E16) -> 46373 | F9: =IF(H9="M","",E9-D9+1) -> 64 | G9: =IFERROR(COUNTIFS(G10:G16,"erledigt",H10:H16,"<>G")/COUNTIFS(H10:H16,"<>G"),0) -> 0 | H9: G | J9: =IF(AND($D9<=J$6,$E9>=J$5),1,"") -> 1 | K9: =IF(AND($D9<=K$6,$E9>=K$5),1,"") -> 1 | L9: =IF(AND($D9<=L$6,$E9>=L$5),1,"") -> 1 | M9: =IF(AND($D9<=M$6,$E9>=M$5),1,"") -> 1 | N9: =IF(AND($D9<=N$6,$E9>=N$5),1,"") -> 1 | O9: =IF(AND($D9<=O$6,$E9>=O$5),1,"") -> 1 | P9: =IF(AND($D9<=P$6,$E9>=P$5),1,"") -> 1 | Q9: =IF(AND($D9<=Q$6,$E9>=Q$5),1,"") -> 1 | ... AF9: =IF(AND($D9<=AF$6,$E9>=AF$5),1,"")
A10: 1.1 | B10: Literaturrecherche (Web of Science, Google Scholar) | C10: Beide | D10: 46310 | E10: 46330 | F10: =IF(H10="M","",E10-D10+1) -> 21 | G10: offen | H10: A | J10: =IF(AND($D10<=J$6,$E10>=J$5),1,"") -> 1 | K10: =IF(AND($D10<=K$6,$E10>=K$5),1,"") -> 1 | L10: =IF(AND($D10<=L$6,$E10>=L$5),1,"") -> 1 | M10: =IF(AND($D10<=M$6,$E10>=M$5),1,"") -> 1 | N10: =IF(AND($D10<=N$6,$E10>=N$5),1,"") | O10: =IF(AND($D10<=O$6,$E10>=O$5),1,"") | P10: =IF(AND($D10<=P$6,$E10>=P$5),1,"") | Q10: =IF(AND($D10<=Q$6,$E10>=Q$5),1,"") | ... AF10: =IF(AND($D10<=AF$6,$E10>=AF$5),1,"")
A11: 1.2 | B11: Paper wählen | C11: Beide | D11: 46324 | E11: 46330 | F11: =IF(H11="M","",E11-D11+1) -> 7 | G11: offen | H11: A | J11: =IF(AND($D11<=J$6,$E11>=J$5),1,"") | K11: =IF(AND($D11<=K$6,$E11>=K$5),1,"") | L11: =IF(AND($D11<=L$6,$E11>=L$5),1,"") -> 1 | M11: =IF(AND($D11<=M$6,$E11>=M$5),1,"") -> 1 | N11: =IF(AND($D11<=N$6,$E11>=N$5),1,"") | O11: =IF(AND($D11<=O$6,$E11>=O$5),1,"") | P11: =IF(AND($D11<=P$6,$E11>=P$5),1,"") | Q11: =IF(AND($D11<=Q$6,$E11>=Q$5),1,"") | ... AF11: =IF(AND($D11<=AF$6,$E11>=AF$5),1,"")
A12: 1.3 | B12: Paper durcharbeiten | C12: Beide | D12: 46331 | E12: 46336 | F12: =IF(H12="M","",E12-D12+1) -> 6 | G12: offen | H12: A | J12: =IF(AND($D12<=J$6,$E12>=J$5),1,"") | K12: =IF(AND($D12<=K$6,$E12>=K$5),1,"") | L12: =IF(AND($D12<=L$6,$E12>=L$5),1,"") | M12: =IF(AND($D12<=M$6,$E12>=M$5),1,"") -> 1 | N12: =IF(AND($D12<=N$6,$E12>=N$5),1,"") -> 1 | O12: =IF(AND($D12<=O$6,$E12>=O$5),1,"") | P12: =IF(AND($D12<=P$6,$E12>=P$5),1,"") | Q12: =IF(AND($D12<=Q$6,$E12>=Q$5),1,"") | ... AF12: =IF(AND($D12<=AF$6,$E12>=AF$5),1,"")
A13: 1.4 | B13: Bewegungsgleichungen | C13: Kristijan | D13: 46324 | E13: 46351 | F13: =IF(H13="M","",E13-D13+1) -> 28 | G13: offen | H13: A | J13: =IF(AND($D13<=J$6,$E13>=J$5),1,"") | K13: =IF(AND($D13<=K$6,$E13>=K$5),1,"") | L13: =IF(AND($D13<=L$6,$E13>=L$5),1,"") -> 1 | M13: =IF(AND($D13<=M$6,$E13>=M$5),1,"") -> 1 | N13: =IF(AND($D13<=N$6,$E13>=N$5),1,"") -> 1 | O13: =IF(AND($D13<=O$6,$E13>=O$5),1,"") -> 1 | P13: =IF(AND($D13<=P$6,$E13>=P$5),1,"") -> 1 | Q13: =IF(AND($D13<=Q$6,$E13>=Q$5),1,"") | ... AF13: =IF(AND($D13<=AF$6,$E13>=AF$5),1,"")
A14: 1.5 | B14: Körperparameter, Trägheitstensor und Trägheitsachsen aus STL | C14: Janosch | D14: 46324 | E14: 46351 | F14: =IF(H14="M","",E14-D14+1) -> 28 | G14: offen | H14: A | J14: =IF(AND($D14<=J$6,$E14>=J$5),1,"") | K14: =IF(AND($D14<=K$6,$E14>=K$5),1,"") | L14: =IF(AND($D14<=L$6,$E14>=L$5),1,"") -> 1 | M14: =IF(AND($D14<=M$6,$E14>=M$5),1,"") -> 1 | N14: =IF(AND($D14<=N$6,$E14>=N$5),1,"") -> 1 | O14: =IF(AND($D14<=O$6,$E14>=O$5),1,"") -> 1 | P14: =IF(AND($D14<=P$6,$E14>=P$5),1,"") -> 1 | Q14: =IF(AND($D14<=Q$6,$E14>=Q$5),1,"") | ... AF14: =IF(AND($D14<=AF$6,$E14>=AF$5),1,"")
A15: 1.6 | B15: Simulation Umkehrdynamik (numerisch) + Moden und Energiebilanz | C15: Kristijan | D15: 46345 | E15: 46373 | F15: =IF(H15="M","",E15-D15+1) -> 29 | G15: offen | H15: A | J15: =IF(AND($D15<=J$6,$E15>=J$5),1,"") | K15: =IF(AND($D15<=K$6,$E15>=K$5),1,"") | L15: =IF(AND($D15<=L$6,$E15>=L$5),1,"") | M15: =IF(AND($D15<=M$6,$E15>=M$5),1,"") | N15: =IF(AND($D15<=N$6,$E15>=N$5),1,"") | O15: =IF(AND($D15<=O$6,$E15>=O$5),1,"") -> 1 | P15: =IF(AND($D15<=P$6,$E15>=P$5),1,"") -> 1 | Q15: =IF(AND($D15<=Q$6,$E15>=Q$5),1,"") -> 1 | ... AF15: =IF(AND($D15<=AF$6,$E15>=AF$5),1,"")
A16: 1.7 | B16: Vorhersage Umkehrzeit vs. Anfangs-ω und δ | C16: Janosch | D16: 46345 | E16: 46373 | F16: =IF(H16="M","",E16-D16+1) -> 29 | G16: offen | H16: A | J16: =IF(AND($D16<=J$6,$E16>=J$5),1,"") | K16: =IF(AND($D16<=K$6,$E16>=K$5),1,"") | L16: =IF(AND($D16<=L$6,$E16>=L$5),1,"") | M16: =IF(AND($D16<=M$6,$E16>=M$5),1,"") | N16: =IF(AND($D16<=N$6,$E16>=N$5),1,"") | O16: =IF(AND($D16<=O$6,$E16>=O$5),1,"") -> 1 | P16: =IF(AND($D16<=P$6,$E16>=P$5),1,"") -> 1 | Q16: =IF(AND($D16<=Q$6,$E16>=Q$5),1,"") -> 1 | ... AF16: =IF(AND($D16<=AF$6,$E16>=AF$5),1,"")
A17: 2 | B17: Materialien | D17: =MIN(D18:D39) -> 46307 | E17: =MAX(E18:E39) -> 46352 | F17: =IF(H17="M","",E17-D17+1) -> 46 | G17: =IFERROR(COUNTIFS(G18:G39,"erledigt",H18:H39,"<>G")/COUNTIFS(H18:H39,"<>G"),0) -> 0 | H17: G | J17: =IF(AND($D17<=J$6,$E17>=J$5),1,"") -> 1 | K17: =IF(AND($D17<=K$6,$E17>=K$5),1,"") -> 1 | L17: =IF(AND($D17<=L$6,$E17>=L$5),1,"") -> 1 | M17: =IF(AND($D17<=M$6,$E17>=M$5),1,"") -> 1 | N17: =IF(AND($D17<=N$6,$E17>=N$5),1,"") -> 1 | O17: =IF(AND($D17<=O$6,$E17>=O$5),1,"") -> 1 | P17: =IF(AND($D17<=P$6,$E17>=P$5),1,"") -> 1 | Q17: =IF(AND($D17<=Q$6,$E17>=Q$5),1,"") | ... AF17: =IF(AND($D17<=AF$6,$E17>=AF$5),1,"")
A18: 2.1 | B18: Sensor | D18: =MIN(D19:D27) -> 46307 | E18: =MAX(E19:E27) -> 46352 | F18: =IF(H18="M","",E18-D18+1) -> 46 | G18: =IFERROR(COUNTIFS(G19:G27,"erledigt",H19:H27,"<>G")/COUNTIFS(H19:H27,"<>G"),0) -> 0 | H18: G | J18: =IF(AND($D18<=J$6,$E18>=J$5),1,"") -> 1 | K18: =IF(AND($D18<=K$6,$E18>=K$5),1,"") -> 1 | L18: =IF(AND($D18<=L$6,$E18>=L$5),1,"") -> 1 | M18: =IF(AND($D18<=M$6,$E18>=M$5),1,"") -> 1 | N18: =IF(AND($D18<=N$6,$E18>=N$5),1,"") -> 1 | O18: =IF(AND($D18<=O$6,$E18>=O$5),1,"") -> 1 | P18: =IF(AND($D18<=P$6,$E18>=P$5),1,"") -> 1 | Q18: =IF(AND($D18<=Q$6,$E18>=Q$5),1,"") | ... AF18: =IF(AND($D18<=AF$6,$E18>=AF$5),1,"")
A19: 2.1.1 | B19: Sensor und Akku festlegen | C19: Beide | D19: 46307 | E19: 46314 | F19: =IF(H19="M","",E19-D19+1) -> 8 | G19: offen | H19: A | J19: =IF(AND($D19<=J$6,$E19>=J$5),1,"") -> 1 | K19: =IF(AND($D19<=K$6,$E19>=K$5),1,"") -> 1 | L19: =IF(AND($D19<=L$6,$E19>=L$5),1,"") | M19: =IF(AND($D19<=M$6,$E19>=M$5),1,"") | N19: =IF(AND($D19<=N$6,$E19>=N$5),1,"") | O19: =IF(AND($D19<=O$6,$E19>=O$5),1,"") | P19: =IF(AND($D19<=P$6,$E19>=P$5),1,"") | Q19: =IF(AND($D19<=Q$6,$E19>=Q$5),1,"") | ... AF19: =IF(AND($D19<=AF$6,$E19>=AF$5),1,"")
A20: 2.1.2 | B20: Auftrag E-Werkstatt | D20: =MIN(D21:D25) -> 46317 | E20: =MAX(E21:E25) -> 46335 | F20: =IF(H20="M","",E20-D20+1) -> 19 | G20: =IFERROR(COUNTIFS(G21:G25,"erledigt",H21:H25,"<>G")/COUNTIFS(H21:H25,"<>G"),0) -> 0 | H20: G | J20: =IF(AND($D20<=J$6,$E20>=J$5),1,"") | K20: =IF(AND($D20<=K$6,$E20>=K$5),1,"") -> 1 | L20: =IF(AND($D20<=L$6,$E20>=L$5),1,"") -> 1 | M20: =IF(AND($D20<=M$6,$E20>=M$5),1,"") -> 1 | N20: =IF(AND($D20<=N$6,$E20>=N$5),1,"") -> 1 | O20: =IF(AND($D20<=O$6,$E20>=O$5),1,"") | P20: =IF(AND($D20<=P$6,$E20>=P$5),1,"") | Q20: =IF(AND($D20<=Q$6,$E20>=Q$5),1,"") | ... AF20: =IF(AND($D20<=AF$6,$E20>=AF$5),1,"")
A21: 2.1.2.1 | B21: Bauteile vorhanden? | C21: Beide | D21: 46317 | E21: 46321 | F21: =IF(H21="M","",E21-D21+1) -> 5 | G21: läuft | H21: A | J21: =IF(AND($D21<=J$6,$E21>=J$5),1,"") | K21: =IF(AND($D21<=K$6,$E21>=K$5),1,"") -> 1 | L21: =IF(AND($D21<=L$6,$E21>=L$5),1,"") -> 1 | M21: =IF(AND($D21<=M$6,$E21>=M$5),1,"") | N21: =IF(AND($D21<=N$6,$E21>=N$5),1,"") | O21: =IF(AND($D21<=O$6,$E21>=O$5),1,"") | P21: =IF(AND($D21<=P$6,$E21>=P$5),1,"") | Q21: =IF(AND($D21<=Q$6,$E21>=Q$5),1,"") | ... AF21: =IF(AND($D21<=AF$6,$E21>=AF$5),1,"")
A22: 2.1.2.2 | B22: Auftrag formulieren | C22: Beide | D22: 46317 | E22: 46323 | F22: =IF(H22="M","",E22-D22+1) -> 7 | G22: läuft | H22: A | J22: =IF(AND($D22<=J$6,$E22>=J$5),1,"") | K22: =IF(AND($D22<=K$6,$E22>=K$5),1,"") -> 1 | L22: =IF(AND($D22<=L$6,$E22>=L$5),1,"") -> 1 | M22: =IF(AND($D22<=M$6,$E22>=M$5),1,"") | N22: =IF(AND($D22<=N$6,$E22>=N$5),1,"") | O22: =IF(AND($D22<=O$6,$E22>=O$5),1,"") | P22: =IF(AND($D22<=P$6,$E22>=P$5),1,"") | Q22: =IF(AND($D22<=Q$6,$E22>=Q$5),1,"") | ... AF22: =IF(AND($D22<=AF$6,$E22>=AF$5),1,"")
A23: 2.1.2.3 | B23: Bauteile vorbeibringen | C23: Beide | D23: 46324 | E23: 46324 | F23: =IF(H23="M","",E23-D23+1) -> 1 | G23: offen | H23: A | J23: =IF(AND($D23<=J$6,$E23>=J$5),1,"") | K23: =IF(AND($D23<=K$6,$E23>=K$5),1,"") | L23: =IF(AND($D23<=L$6,$E23>=L$5),1,"") -> 1 | M23: =IF(AND($D23<=M$6,$E23>=M$5),1,"") | N23: =IF(AND($D23<=N$6,$E23>=N$5),1,"") | O23: =IF(AND($D23<=O$6,$E23>=O$5),1,"") | P23: =IF(AND($D23<=P$6,$E23>=P$5),1,"") | Q23: =IF(AND($D23<=Q$6,$E23>=Q$5),1,"") | ... AF23: =IF(AND($D23<=AF$6,$E23>=AF$5),1,"")
A24: 2.1.2.4 | B24: Bearbeitung E-Werkstatt (extern, Wartezeit) | C24: offen | D24: 46325 | E24: 46328 | F24: =IF(H24="M","",E24-D24+1) -> 4 | G24: offen | H24: A | J24: =IF(AND($D24<=J$6,$E24>=J$5),1,"") | K24: =IF(AND($D24<=K$6,$E24>=K$5),1,"") | L24: =IF(AND($D24<=L$6,$E24>=L$5),1,"") -> 1 | M24: =IF(AND($D24<=M$6,$E24>=M$5),1,"") -> 1 | N24: =IF(AND($D24<=N$6,$E24>=N$5),1,"") | O24: =IF(AND($D24<=O$6,$E24>=O$5),1,"") | P24: =IF(AND($D24<=P$6,$E24>=P$5),1,"") | Q24: =IF(AND($D24<=Q$6,$E24>=Q$5),1,"") | ... AF24: =IF(AND($D24<=AF$6,$E24>=AF$5),1,"")
A25: 2.1.2.5 | B25: Platine abholen + Funktionstest | C25: Beide | D25: 46328 | E25: 46335 | F25: =IF(H25="M","",E25-D25+1) -> 8 | G25: offen | H25: A | J25: =IF(AND($D25<=J$6,$E25>=J$5),1,"") | K25: =IF(AND($D25<=K$6,$E25>=K$5),1,"") | L25: =IF(AND($D25<=L$6,$E25>=L$5),1,"") | M25: =IF(AND($D25<=M$6,$E25>=M$5),1,"") -> 1 | N25: =IF(AND($D25<=N$6,$E25>=N$5),1,"") -> 1 | O25: =IF(AND($D25<=O$6,$E25>=O$5),1,"") | P25: =IF(AND($D25<=P$6,$E25>=P$5),1,"") | Q25: =IF(AND($D25<=Q$6,$E25>=Q$5),1,"") | ... AF25: =IF(AND($D25<=AF$6,$E25>=AF$5),1,"")
A26: 2.1.3 | B26: Firmware: auslesen + loggen/streamen | C26: Kristijan | D26: 46331 | E26: 46352 | F26: =IF(H26="M","",E26-D26+1) -> 22 | G26: offen | H26: A | J26: =IF(AND($D26<=J$6,$E26>=J$5),1,"") | K26: =IF(AND($D26<=K$6,$E26>=K$5),1,"") | L26: =IF(AND($D26<=L$6,$E26>=L$5),1,"") | M26: =IF(AND($D26<=M$6,$E26>=M$5),1,"") -> 1 | N26: =IF(AND($D26<=N$6,$E26>=N$5),1,"") -> 1 | O26: =IF(AND($D26<=O$6,$E26>=O$5),1,"") -> 1 | P26: =IF(AND($D26<=P$6,$E26>=P$5),1,"") -> 1 | Q26: =IF(AND($D26<=Q$6,$E26>=Q$5),1,"") | ... AF26: =IF(AND($D26<=AF$6,$E26>=AF$5),1,"")
A27: 2.1.4 | B27: Kalibrierung (Gyro-Bias, Achsen) | C27: Kristijan | D27: 46331 | E27: 46352 | F27: =IF(H27="M","",E27-D27+1) -> 22 | G27: offen | H27: A | J27: =IF(AND($D27<=J$6,$E27>=J$5),1,"") | K27: =IF(AND($D27<=K$6,$E27>=K$5),1,"") | L27: =IF(AND($D27<=L$6,$E27>=L$5),1,"") | M27: =IF(AND($D27<=M$6,$E27>=M$5),1,"") -> 1 | N27: =IF(AND($D27<=N$6,$E27>=N$5),1,"") -> 1 | O27: =IF(AND($D27<=O$6,$E27>=O$5),1,"") -> 1 | P27: =IF(AND($D27<=P$6,$E27>=P$5),1,"") -> 1 | Q27: =IF(AND($D27<=Q$6,$E27>=Q$5),1,"") | ... AF27: =IF(AND($D27<=AF$6,$E27>=AF$5),1,"")
A28: 2.2 | B28: Wackelstein | D28: =MIN(D29:D39) -> 46307 | E28: =MAX(E29:E39) -> 46338 | F28: =IF(H28="M","",E28-D28+1) -> 32 | G28: =IFERROR(COUNTIFS(G29:G39,"erledigt",H29:H39,"<>G")/COUNTIFS(H29:H39,"<>G"),0) -> 0 | H28: G | J28: =IF(AND($D28<=J$6,$E28>=J$5),1,"") -> 1 | K28: =IF(AND($D28<=K$6,$E28>=K$5),1,"") -> 1 | L28: =IF(AND($D28<=L$6,$E28>=L$5),1,"") -> 1 | M28: =IF(AND($D28<=M$6,$E28>=M$5),1,"") -> 1 | N28: =IF(AND($D28<=N$6,$E28>=N$5),1,"") -> 1 | O28: =IF(AND($D28<=O$6,$E28>=O$5),1,"") | P28: =IF(AND($D28<=P$6,$E28>=P$5),1,"") | Q28: =IF(AND($D28<=Q$6,$E28>=Q$5),1,"") | ... AF28: =IF(AND($D28<=AF$6,$E28>=AF$5),1,"")
A29: 2.2.1 | B29: Prototyp (nur Stein) | D29: =MIN(D30:D35) -> 46307 | E29: =MAX(E30:E35) -> 46334 | F29: =IF(H29="M","",E29-D29+1) -> 28 | G29: =IFERROR(COUNTIFS(G30:G35,"erledigt",H30:H35,"<>G")/COUNTIFS(H30:H35,"<>G"),0) -> 0 | H29: G | J29: =IF(AND($D29<=J$6,$E29>=J$5),1,"") -> 1 | K29: =IF(AND($D29<=K$6,$E29>=K$5),1,"") -> 1 | L29: =IF(AND($D29<=L$6,$E29>=L$5),1,"") -> 1 | M29: =IF(AND($D29<=M$6,$E29>=M$5),1,"") -> 1 | N29: =IF(AND($D29<=N$6,$E29>=N$5),1,"") | O29: =IF(AND($D29<=O$6,$E29>=O$5),1,"") | P29: =IF(AND($D29<=P$6,$E29>=P$5),1,"") | Q29: =IF(AND($D29<=Q$6,$E29>=Q$5),1,"") | ... AF29: =IF(AND($D29<=AF$6,$E29>=AF$5),1,"")
A30: 2.2.1.1 | B30: STL erstellen für Teststeine | C30: Janosch | D30: 46307 | E30: 46314 | F30: =IF(H30="M","",E30-D30+1) -> 8 | G30: offen | H30: A | J30: =IF(AND($D30<=J$6,$E30>=J$5),1,"") -> 1 | K30: =IF(AND($D30<=K$6,$E30>=K$5),1,"") -> 1 | L30: =IF(AND($D30<=L$6,$E30>=L$5),1,"") | M30: =IF(AND($D30<=M$6,$E30>=M$5),1,"") | N30: =IF(AND($D30<=N$6,$E30>=N$5),1,"") | O30: =IF(AND($D30<=O$6,$E30>=O$5),1,"") | P30: =IF(AND($D30<=P$6,$E30>=P$5),1,"") | Q30: =IF(AND($D30<=Q$6,$E30>=Q$5),1,"") | ... AF30: =IF(AND($D30<=AF$6,$E30>=AF$5),1,"")
A31: 2.2.1.2 | B31: STL drucken lassen | C31: Janosch | D31: 46314 | E31: 46324 | F31: =IF(H31="M","",E31-D31+1) -> 11 | G31: läuft | H31: A | J31: =IF(AND($D31<=J$6,$E31>=J$5),1,"") | K31: =IF(AND($D31<=K$6,$E31>=K$5),1,"") -> 1 | L31: =IF(AND($D31<=L$6,$E31>=L$5),1,"") -> 1 | M31: =IF(AND($D31<=M$6,$E31>=M$5),1,"") | N31: =IF(AND($D31<=N$6,$E31>=N$5),1,"") | O31: =IF(AND($D31<=O$6,$E31>=O$5),1,"") | P31: =IF(AND($D31<=P$6,$E31>=P$5),1,"") | Q31: =IF(AND($D31<=Q$6,$E31>=Q$5),1,"") | ... AF31: =IF(AND($D31<=AF$6,$E31>=AF$5),1,"")
A32: 2.2.1.3 | B32: 3D-Druck schleifen | C32: Beide | D32: 46324 | E32: 46324 | F32: =IF(H32="M","",E32-D32+1) -> 1 | G32: offen | H32: A | J32: =IF(AND($D32<=J$6,$E32>=J$5),1,"") | K32: =IF(AND($D32<=K$6,$E32>=K$5),1,"") | L32: =IF(AND($D32<=L$6,$E32>=L$5),1,"") -> 1 | M32: =IF(AND($D32<=M$6,$E32>=M$5),1,"") | N32: =IF(AND($D32<=N$6,$E32>=N$5),1,"") | O32: =IF(AND($D32<=O$6,$E32>=O$5),1,"") | P32: =IF(AND($D32<=P$6,$E32>=P$5),1,"") | Q32: =IF(AND($D32<=Q$6,$E32>=Q$5),1,"") | ... AF32: =IF(AND($D32<=AF$6,$E32>=AF$5),1,"")
A33: 2.2.1.4 | B33: Funktionalität testen | C33: Beide | D33: 46324 | E33: 46324 | F33: =IF(H33="M","",E33-D33+1) -> 1 | G33: offen | H33: A | J33: =IF(AND($D33<=J$6,$E33>=J$5),1,"") | K33: =IF(AND($D33<=K$6,$E33>=K$5),1,"") | L33: =IF(AND($D33<=L$6,$E33>=L$5),1,"") -> 1 | M33: =IF(AND($D33<=M$6,$E33>=M$5),1,"") | N33: =IF(AND($D33<=N$6,$E33>=N$5),1,"") | O33: =IF(AND($D33<=O$6,$E33>=O$5),1,"") | P33: =IF(AND($D33<=P$6,$E33>=P$5),1,"") | Q33: =IF(AND($D33<=Q$6,$E33>=Q$5),1,"") | ... AF33: =IF(AND($D33<=AF$6,$E33>=AF$5),1,"")
A34: 2.2.1.5 | B34: Mögliche Verbesserungen vornehmen | C34: Beide | D34: 46324 | E34: 46331 | F34: =IF(H34="M","",E34-D34+1) -> 8 | G34: offen | H34: A | J34: =IF(AND($D34<=J$6,$E34>=J$5),1,"") | K34: =IF(AND($D34<=K$6,$E34>=K$5),1,"") | L34: =IF(AND($D34<=L$6,$E34>=L$5),1,"") -> 1 | M34: =IF(AND($D34<=M$6,$E34>=M$5),1,"") -> 1 | N34: =IF(AND($D34<=N$6,$E34>=N$5),1,"") | O34: =IF(AND($D34<=O$6,$E34>=O$5),1,"") | P34: =IF(AND($D34<=P$6,$E34>=P$5),1,"") | Q34: =IF(AND($D34<=Q$6,$E34>=Q$5),1,"") | ... AF34: =IF(AND($D34<=AF$6,$E34>=AF$5),1,"")
A35: 2.2.1.6 | B35: Neuer Prototyp | C35: Janosch | D35: 46331 | E35: 46334 | F35: =IF(H35="M","",E35-D35+1) -> 4 | G35: offen | H35: A | J35: =IF(AND($D35<=J$6,$E35>=J$5),1,"") | K35: =IF(AND($D35<=K$6,$E35>=K$5),1,"") | L35: =IF(AND($D35<=L$6,$E35>=L$5),1,"") | M35: =IF(AND($D35<=M$6,$E35>=M$5),1,"") -> 1 | N35: =IF(AND($D35<=N$6,$E35>=N$5),1,"") | O35: =IF(AND($D35<=O$6,$E35>=O$5),1,"") | P35: =IF(AND($D35<=P$6,$E35>=P$5),1,"") | Q35: =IF(AND($D35<=Q$6,$E35>=Q$5),1,"") | ... AF35: =IF(AND($D35<=AF$6,$E35>=AF$5),1,"")
A36: 2.2.2 | B36: Messkörper mit Sensorfach | D36: =MIN(D37:D39) -> 46331 | E36: =MAX(E37:E39) -> 46338 | F36: =IF(H36="M","",E36-D36+1) -> 8 | G36: =IFERROR(COUNTIFS(G37:G39,"erledigt",H37:H39,"<>G")/COUNTIFS(H37:H39,"<>G"),0) -> 0 | H36: G | J36: =IF(AND($D36<=J$6,$E36>=J$5),1,"") | K36: =IF(AND($D36<=K$6,$E36>=K$5),1,"") | L36: =IF(AND($D36<=L$6,$E36>=L$5),1,"") | M36: =IF(AND($D36<=M$6,$E36>=M$5),1,"") -> 1 | N36: =IF(AND($D36<=N$6,$E36>=N$5),1,"") -> 1 | O36: =IF(AND($D36<=O$6,$E36>=O$5),1,"") | P36: =IF(AND($D36<=P$6,$E36>=P$5),1,"") | Q36: =IF(AND($D36<=Q$6,$E36>=Q$5),1,"") | ... AF36: =IF(AND($D36<=AF$6,$E36>=AF$5),1,"")
A37: 2.2.2.1 | B37: CAD: Sensorfach, Masse ausbalancieren | C37: Janosch | D37: 46335 | E37: 46335 | F37: =IF(H37="M","",E37-D37+1) -> 1 | G37: offen | H37: A | J37: =IF(AND($D37<=J$6,$E37>=J$5),1,"") | K37: =IF(AND($D37<=K$6,$E37>=K$5),1,"") | L37: =IF(AND($D37<=L$6,$E37>=L$5),1,"") | M37: =IF(AND($D37<=M$6,$E37>=M$5),1,"") | N37: =IF(AND($D37<=N$6,$E37>=N$5),1,"") -> 1 | O37: =IF(AND($D37<=O$6,$E37>=O$5),1,"") | P37: =IF(AND($D37<=P$6,$E37>=P$5),1,"") | Q37: =IF(AND($D37<=Q$6,$E37>=Q$5),1,"") | ... AF37: =IF(AND($D37<=AF$6,$E37>=AF$5),1,"")
A38: 2.2.2.2 | B38: Drucken + Sensor einbauen | C38: Janosch | D38: 46331 | E38: 46338 | F38: =IF(H38="M","",E38-D38+1) -> 8 | G38: offen | H38: A | J38: =IF(AND($D38<=J$6,$E38>=J$5),1,"") | K38: =IF(AND($D38<=K$6,$E38>=K$5),1,"") | L38: =IF(AND($D38<=L$6,$E38>=L$5),1,"") | M38: =IF(AND($D38<=M$6,$E38>=M$5),1,"") -> 1 | N38: =IF(AND($D38<=N$6,$E38>=N$5),1,"") -> 1 | O38: =IF(AND($D38<=O$6,$E38>=O$5),1,"") | P38: =IF(AND($D38<=P$6,$E38>=P$5),1,"") | Q38: =IF(AND($D38<=Q$6,$E38>=Q$5),1,"") | ... AF38: =IF(AND($D38<=AF$6,$E38>=AF$5),1,"")
A39: 2.2.2.3 | B39: Masse + Schwerpunkt nachmessen | C39: Janosch | D39: 46338 | E39: 46338 | F39: =IF(H39="M","",E39-D39+1) -> 1 | G39: offen | H39: A | J39: =IF(AND($D39<=J$6,$E39>=J$5),1,"") | K39: =IF(AND($D39<=K$6,$E39>=K$5),1,"") | L39: =IF(AND($D39<=L$6,$E39>=L$5),1,"") | M39: =IF(AND($D39<=M$6,$E39>=M$5),1,"") | N39: =IF(AND($D39<=N$6,$E39>=N$5),1,"") -> 1 | O39: =IF(AND($D39<=O$6,$E39>=O$5),1,"") | P39: =IF(AND($D39<=P$6,$E39>=P$5),1,"") | Q39: =IF(AND($D39<=Q$6,$E39>=Q$5),1,"") | ... AF39: =IF(AND($D39<=AF$6,$E39>=AF$5),1,"")
A40: 3 | B40: Versuchsaufbau | D40: =MIN(D41:D48) -> 46317 | E40: =MAX(E41:E48) -> 46370 | F40: =IF(H40="M","",E40-D40+1) -> 54 | G40: =IFERROR(COUNTIFS(G41:G48,"erledigt",H41:H48,"<>G")/COUNTIFS(H41:H48,"<>G"),0) -> 0 | H40: G | J40: =IF(AND($D40<=J$6,$E40>=J$5),1,"") | K40: =IF(AND($D40<=K$6,$E40>=K$5),1,"") -> 1 | L40: =IF(AND($D40<=L$6,$E40>=L$5),1,"") -> 1 | M40: =IF(AND($D40<=M$6,$E40>=M$5),1,"") -> 1 | N40: =IF(AND($D40<=N$6,$E40>=N$5),1,"") -> 1 | O40: =IF(AND($D40<=O$6,$E40>=O$5),1,"") -> 1 | P40: =IF(AND($D40<=P$6,$E40>=P$5),1,"") -> 1 | Q40: =IF(AND($D40<=Q$6,$E40>=Q$5),1,"") -> 1 | ... AF40: =IF(AND($D40<=AF$6,$E40>=AF$5),1,"")
...

Sheet Termine
B2: Termine & Quellen
B3: Projektpraktikum WS 26/27 · Dynamik Keltischer Wackelsteine · Kristijan & Janosch
B5: Datum | C5: Tag | D5: KW | E5: Abgabe / Termin | F5: Art | G5: Quelle | H5: noch Tage
B6: 46310 | C6: =MID("MoDiMiDoFrSaSo",WEEKDAY(B6,2)*2-1,2) -> Do | D6: =_xlfn.ISOWEEKNUM(B6) -> 42 | E6: Endgültige Wahl Schwerpunktthema | F6: Pflicht | G6: Moodle (Portfolio-PDF S. 4) | H6: =B6-TODAY() -> -7
B7: 46316 | C7: =MID("MoDiMiDoFrSaSo",WEEKDAY(B7,2)*2-1,2) -> Mi | D7: =_xlfn.ISOWEEKNUM(B7) -> 43 | E7: Motivationsformular | F7: Pflicht | G7: Moodle (Portfolio-PDF S. 4) | H7: =B7-TODAY() -> -1
B8: 46323 | C8: =MID("MoDiMiDoFrSaSo",WEEKDAY(B8,2)*2-1,2) -> Mi | D8: =_xlfn.ISOWEEKNUM(B8) -> 44 | E8: Arbeitsplan + Reflexion | F8: Pflicht | G8: Moodle (Portfolio-PDF S. 4) | H8: =B8-TODAY() -> 6
B9: 46337 | C9: =MID("MoDiMiDoFrSaSo",WEEKDAY(B9,2)*2-1,2) -> Mi | D9: =_xlfn.ISOWEEKNUM(B9) -> 46 | E9: Wissenschaftliche Arbeit + Reflexion | F9: Pflicht | G9: Moodle (Portfolio-PDF S. 4) | H9: =B9-TODAY() -> 20
B10: 46365 | C10: =MID("MoDiMiDoFrSaSo",WEEKDAY(B10,2)*2-1,2) -> Mi | D10: =_xlfn.ISOWEEKNUM(B10) -> 50 | E10: Protokoll eines Praktikumstages + Reflexion | F10: Pflicht | G10: Moodle (Portfolio-PDF S. 4) | H10: =B10-TODAY() -> 48
B11: 46407 | C11: =MID("MoDiMiDoFrSaSo",WEEKDAY(B11,2)*2-1,2) -> Mi | D11: =_xlfn.ISOWEEKNUM(B11) -> 3 | E11: Messergebnis + Reflexion | F11: Pflicht | G11: Moodle (Portfolio-PDF S. 4) | H11: =B11-TODAY() -> 90
B12: 46410 | C12: =MID("MoDiMiDoFrSaSo",WEEKDAY(B12,2)*2-1,2) -> Sa | D12: =_xlfn.ISOWEEKNUM(B12) -> 3 | E12: Anmeldung mündl. Prüfung (Hochschulportal) | F12: Pflicht? | G12: Plan Petros – im Portal prüfen! | H12: =B12-TODAY() -> 93
B13: 46414 | C13: =MID("MoDiMiDoFrSaSo",WEEKDAY(B13,2)*2-1,2) -> Mi | D13: =_xlfn.ISOWEEKNUM(B13) -> 4 | E13: Vortragsfolien + Zusatzmaterial | F13: Pflicht | G13: Moodle (Portfolio-PDF S. 4) | H13: =B13-TODAY() -> 97
B14: 46415 | C14: =MID("MoDiMiDoFrSaSo",WEEKDAY(B14,2)*2-1,2) -> Do | D14: =_xlfn.ISOWEEKNUM(B14) -> 4 | E14: Vorträge Projektpraktikum (Prüfung, Anwesenheitspflicht) | F14: Pflicht | G14: Moodle + Google Kalender | H14: =B14-TODAY() -> 98
B15: 46425 | C15: =MID("MoDiMiDoFrSaSo",WEEKDAY(B15,2)*2-1,2) -> So | D15: =_xlfn.ISOWEEKNUM(B15) -> 5 | E15: Vortragsfolien + Kommentar + Reflexion | F15: empfohlen | G15: Moodle (Portfolio-PDF S. 4) | H15: =B15-TODAY() -> 108
B16: 46439 | C16: =MID("MoDiMiDoFrSaSo",WEEKDAY(B16,2)*2-1,2) -> So | D16: =_xlfn.ISOWEEKNUM(B16) -> 7 | E16: Aussage aus anderem Vortrag + Reflexion | F16: empfohlen | G16: Moodle (Portfolio-PDF S. 4) | H16: =B16-TODAY() -> 122
B17: 46456 | C17: =MID("MoDiMiDoFrSaSo",WEEKDAY(B17,2)*2-1,2) -> Mi | D17: =_xlfn.ISOWEEKNUM(B17) -> 10 | E17: Anmeldung schriftl. Teil (Hochschulportal) | F17: Pflicht? | G17: Plan Petros – im Portal prüfen! | H17: =B17-TODAY() -> 139
B18: 46461 | C18: =MID("MoDiMiDoFrSaSo",WEEKDAY(B18,2)*2-1,2) -> Mo | D18: =_xlfn.ISOWEEKNUM(B18) -> 11 | E18: Endabgabe Portfolio (verspätet = nicht bestanden) | F18: Pflicht | G18: Moodle (Portfolio-PDF S. 4) | H18: =B18-TODAY() -> 144
B21: Praktikumstage (Google Kalender: Do 10–12 Uhr, O26/233 bzw. O26/234)
B22: 46310 | C22: =MID("MoDiMiDoFrSaSo",WEEKDAY(B22,2)*2-1,2) -> Do
B23: 46317 | C23: =MID("MoDiMiDoFrSaSo",WEEKDAY(B23,2)*2-1,2) -> Do
B24: 46324 | C24: =MID("MoDiMiDoFrSaSo",WEEKDAY(B24,2)*2-1,2) -> Do
B25: 46331 | C25: =MID("MoDiMiDoFrSaSo",WEEKDAY(B25,2)*2-1,2) -> Do
B26: 46338 | C26: =MID("MoDiMiDoFrSaSo",WEEKDAY(B26,2)*2-1,2) -> Do
B27: 46345 | C27: =MID("MoDiMiDoFrSaSo",WEEKDAY(B27,2)*2-1,2) -> Do
B28: 46352 | C28: =MID("MoDiMiDoFrSaSo",WEEKDAY(B28,2)*2-1,2) -> Do
B29: 46359 | C29: =MID("MoDiMiDoFrSaSo",WEEKDAY(B29,2)*2-1,2) -> Do
B30: 46366 | C30: =MID("MoDiMiDoFrSaSo",WEEKDAY(B30,2)*2-1,2) -> Do
B31: 46373 | C31: =MID("MoDiMiDoFrSaSo",WEEKDAY(B31,2)*2-1,2) -> Do
B32: 46401 | C32: =MID("MoDiMiDoFrSaSo",WEEKDAY(B32,2)*2-1,2) -> Do
B33: 46408 | C33: =MID("MoDiMiDoFrSaSo",WEEKDAY(B33,2)*2-1,2) -> Do
... B36: 46429 | C36: =MID("MoDiMiDoFrSaSo",WEEKDAY(B36,2)*2-1,2) -> Do
E41: ↑ freie Zeilen für zusätzliche Termine
B44: Praktikumspause
B45: 46374 | C45: bis | D45: 46400 | E45: kein Praktikumstermin im Kalender zwischen 17.12. und 14.01.
B48: So funktioniert der Plan
B49: • | C49: Wer: Dropdown in Spalte C (Arbeitsplan) → Balken färbt sich automatisch in der Personenfarbe.
B50: • | C50: Namen ändern: Legende oben im Arbeitsplan (C2:D2) überschreiben – Dropdown und Farben ziehen mit.
B51: • | C51: Farben ändern: Start → Bedingte Formatierung → Regeln verwalten → Regeln „=$C9=$C$2“ (Person 1) usw. bearbeiten.
B52: • | C52: Termine verschieben: Start/Ende (Spalten D/E) ändern – Balken, Tage und Gruppen-Summen rechnen neu.
B53: • | C53: Abgabedaten nur hier im Blatt Termine ändern – die ◆-Zeilen im Arbeitsplan verweisen hierher.
B54: • | C54: Status: offen / läuft / erledigt. Gruppen zeigen den Fortschritt in %. Überfällige Aufgaben werden rot.
...
